Traceback (most recent call last):
  File "/Users/jordanbarker/miniconda3/envs/py311/lib/python3.11/site-packages/jupyter_cache/executors/utils.py", line 58, in single_nb_execution
    executenb(
  File "/Users/jordanbarker/miniconda3/envs/py311/lib/python3.11/site-packages/nbclient/client.py", line 1305, in execute
    return NotebookClient(nb=nb, resources=resources, km=km, **kwargs).execute()
           ^^^^^^^^^^^^^^^^^^^^^^^^^^^^^^^^^^^^^^^^^^^^^^^^^^^^^^^^^^^^^^^^^^^^^
  File "/Users/jordanbarker/miniconda3/envs/py311/lib/python3.11/site-packages/jupyter_core/utils/__init__.py", line 173, in wrapped
    return loop.run_until_complete(inner)
           ^^^^^^^^^^^^^^^^^^^^^^^^^^^^^^
  File "/Users/jordanbarker/miniconda3/envs/py311/lib/python3.11/asyncio/base_events.py", line 653, in run_until_complete
    return future.result()
           ^^^^^^^^^^^^^^^
  File "/Users/jordanbarker/miniconda3/envs/py311/lib/python3.11/site-packages/nbclient/client.py", line 705, in async_execute
    await self.async_execute_cell(
  File "/Users/jordanbarker/miniconda3/envs/py311/lib/python3.11/site-packages/nbclient/client.py", line 1058, in async_execute_cell
    await self._check_raise_for_error(cell, cell_index, exec_reply)
  File "/Users/jordanbarker/miniconda3/envs/py311/lib/python3.11/site-packages/nbclient/client.py", line 914, in _check_raise_for_error
    raise CellExecutionError.from_cell_and_msg(cell, exec_reply_content)
nbclient.exceptions.CellExecutionError: An error occurred while executing the following cell:
------------------
E['pi'] = 3.14# Creates a new column (variable) named â€˜xâ€™ and sets all values in column = 3.
display(E)
del E['pi']

# Adding an entire row
new_row = {0:'shrug', 'w':-5, 'x':'e'}
E = E.append(new_row, ignore_index=True)

# Setting specific cell value
#df.at[row,col]
E.at[0,0] = 'at 0,0 test'
E.loc[1,0] = 'loc 0,1 test'

display(E)
------------------


[0;31m---------------------------------------------------------------------------[0m
[0;31mAttributeError[0m                            Traceback (most recent call last)
[0;32m/var/folders/tl/00b3nkg57wz5g7fsvwlb_76m0000gn/T/ipykernel_61955/308143118.py[0m in [0;36m?[0;34m()[0m
[1;32m      3[0m [0;32mdel[0m [0mE[0m[0;34m[[0m[0;34m'pi'[0m[0;34m][0m[0;34m[0m[0;34m[0m[0m
[1;32m      4[0m [0;34m[0m[0m
[1;32m      5[0m [0;31m# Adding an entire row[0m[0;34m[0m[0;34m[0m[0m
[1;32m      6[0m [0mnew_row[0m [0;34m=[0m [0;34m{[0m[0;36m0[0m[0;34m:[0m[0;34m'shrug'[0m[0;34m,[0m [0;34m'w'[0m[0;34m:[0m[0;34m-[0m[0;36m5[0m[0;34m,[0m [0;34m'x'[0m[0;34m:[0m[0;34m'e'[0m[0;34m}[0m[0;34m[0m[0;34m[0m[0m
[0;32m----> 7[0;31m [0mE[0m [0;34m=[0m [0mE[0m[0;34m.[0m[0mappend[0m[0;34m([0m[0mnew_row[0m[0;34m,[0m [0mignore_index[0m[0;34m=[0m[0;32mTrue[0m[0;34m)[0m[0;34m[0m[0;34m[0m[0m
[0m[1;32m      8[0m [0;34m[0m[0m
[1;32m      9[0m [0;31m# Setting specific cell value[0m[0;34m[0m[0;34m[0m[0m
[1;32m     10[0m [0;31m#df.at[row,col][0m[0;34m[0m[0;34m[0m[0m

[0;32m~/miniconda3/envs/py311/lib/python3.11/site-packages/pandas/core/generic.py[0m in [0;36m?[0;34m(self, name)[0m
[1;32m   6292[0m             [0;32mand[0m [0mname[0m [0;32mnot[0m [0;32min[0m [0mself[0m[0;34m.[0m[0m_accessors[0m[0;34m[0m[0;34m[0m[0m
[1;32m   6293[0m             [0;32mand[0m [0mself[0m[0;34m.[0m[0m_info_axis[0m[0;34m.[0m[0m_can_hold_identifiers_and_holds_name[0m[0;34m([0m[0mname[0m[0;34m)[0m[0;34m[0m[0;34m[0m[0m
[1;32m   6294[0m         ):
[1;32m   6295[0m             [0;32mreturn[0m [0mself[0m[0;34m[[0m[0mname[0m[0;34m][0m[0;34m[0m[0;34m[0m[0m
[0;32m-> 6296[0;31m         [0;32mreturn[0m [0mobject[0m[0;34m.[0m[0m__getattribute__[0m[0;34m([0m[0mself[0m[0;34m,[0m [0mname[0m[0;34m)[0m[0;34m[0m[0;34m[0m[0m
[0m
[0;31mAttributeError[0m: 'DataFrame' object has no attribute 'append'

